package com.assignment4;

import java.util.Scanner;

public class Exception {
public static void main(String[] args) {
	Scanner sc = null;
	try {
	sc = new Scanner(System.in);
	System.out.println("Enter Num1: ");
	int num1 = sc.nextInt();
	System.out.println("Enter Num2: ");
	int num2 = sc.nextInt();
	if(num2 == 0)
		throw new ArithmeticException("Divide by zero Exception");
	int result = num1/num2;
	System.out.println("Result: "+ result);
	}catch( ArithmeticException ex ) {
		System.out.println("Inside Catch Block");
		ex.printStackTrace();
	}finally {
		sc.close();
		System.out.println("Inside Finally Block");
	}
}

}


